Workbook

Sheet INCOME WITHDRWAL STATE
A1: CASH/BANK INCOME STATE Sep 2026
A2: SER NO. | B2: DATED | C2: PARTICULAR/ DETAIL | D2: IN CASH | E2: IN BANK | F2: TOTAL | G2: IN CASH | J2: IN BANK | O2: TOTAL
G3: CEO | H3: CFO | I3: DIR OPS | J3: CO'S ACCT (ALLIED) | K3: CO'S ACCT (ASKARI) | L3: CFO'S ACCT | M3: CEO ACC | N3: SONERI ACC
A4: BBF | J4: 707902 | K4: 3620818 | L4: -334707 | M4: 55555 | N4: 775855 | R4: -1119514
A5: 1 | B5: 46267 | C5: WUSAT | D5: 264000 | F5: =SUM(D5:E5) -> 264000 | G5: 264000 | O5: =SUM(G5:N5) -> 264000 | R5: PCI/PFM/68HS | T5: =F28+F26+F13 -> 646000
A6: 2 | B6: 46279 | C6: ELYSIUM | E6: 36000 | F6: =SUM(D6:E6) -> 36000 | L6: 36000 | O6: =SUM(G6:N6) -> 36000
A7: 3 | B7: 46275 | C7: EMAAR | E7: 4754162 | F7: =SUM(D7:E7) -> 4754162 | K7: 4754162 | O7: =SUM(G7:N7) -> 4754162 | R7: -1119514
A8: 4 | B8: 46273 | C8: DHA DENTAL LAB | E8: 35000 | F8: =SUM(D8:E8) -> 35000 | K8: 500 | L8: 35000 | O8: =SUM(G8:N8) -> 35500
A9: 5 | B9: 46279 | C9: DEPOSIT FROM ABL | E9: 0 | F9: =SUM(D9:E9) -> 0 | K9: 250000 | O9: =SUM(G9:N9) -> 250000
A10: 6 | B10: 46279 | C10: CASH DEPOSIT FROM ABL IN CFO ACC | F10: =SUM(D10:E10) -> 0 | K10: 0 | L10: 550000 | O10: =SUM(G10:N10) -> 550000
A11: 7 | B11: 46272 | C11: MIU (AJK BANK) | E11: 1246511 | F11: =SUM(D11:E11) -> 1246511 | N11: 1246511 | O11: =SUM(G11:N11) -> 1246511
A12: 8 | B12: 46266 | C12: CBR | E12: =214272*2 -> 428544 | F12: =SUM(D12:E12) -> 428544 | N12: 428544 | O12: =SUM(G12:N12) -> 428544 | R12: =264000-55000 -> 209000
A13: 9 | B13: 46273 | C13: 68 HS | E13: 204000 | F13: =SUM(D13:E13) -> 204000 | L13: 204000 | O13: =SUM(G13:N13) -> 204000 | R13: =R12-157668 -> 51332
A14: 10 | B14: 46287 | C14: KALOON CHEMICALS | D14: 24000 | F14: =SUM(D14:E14) -> 24000 | L14: 24000 | O14: =SUM(G14:N14) -> 24000
A15: 11 | B15: 46286 | C15: HMC TAXILA | E15: 4629379 | F15: =SUM(D15:E15) -> 4629379 | K15: 4629379 | O15: =SUM(G15:N15) -> 4629379
A16: 12 | B16: 46294 | C16: NOVA | D16: 1900000 | F16: =SUM(D16:E16) -> 1900000 | G16: 1900000 | O16: =SUM(G16:N16) -> 1900000
A17: 13 | B17: 46282 | C17: J SONS | E17: 38500 | F17: =SUM(D17:E17) -> 38500 | L17: 38500 | O17: =SUM(G17:N17) -> 38500
A18: 14 | B18: 46287 | C18: MR SALAAR/Gulreiz | F18: =SUM(D18:E18) -> 0 | O18: =SUM(G18:N18) -> 0
A19: 15 | B19: 46266 | C19: RISING SUN LODGES | D19: 90000 | F19: =SUM(D19:E19) -> 90000 | H19: 0 | L19: 90000 | O19: =SUM(G19:N19) -> 90000
A20: 16 | B20: 46273 | C20: PRG | E20: 65340 | F20: =SUM(D20:E20) -> 65340 | L20: 65340 | O20: =SUM(G20:N20) -> 65340
A21: 17 | B21: 46273 | C21: SWEET PALACE | D21: 90000 | F21: =SUM(D21:E21) -> 90000 | G21: 90000 | O21: =SUM(G21:N21) -> 90000
A22: 18 | B22: 46272 | C22: AWT | E22: 148000 | F22: =SUM(D22:E22) -> 148000 | L22: 148000 | O22: =SUM(G22:N22) -> 148000
A23: 19 | B23: 46275 | C23: DOLMEN | E23: 510152 | F23: =SUM(D23:E23) -> 510152 | J23: 510152 | O23: =SUM(G23:N23) -> 510152
A24: 20 | B24: 46269 | C24: SGC SERVICES | E24: 68752 | F24: =SUM(D24:E24) -> 68752 | J24: 68752 | O24: =SUM(G24:N24) -> 68752
A25: 21 | B25: 46269 | C25: SGC THALIAN | E25: 745927 | F25: =SUM(D25:E25) -> 745927 | J25: 745927 | O25: =SUM(G25:N25) -> 745927
A26: 22 | B26: 46286 | C26: PFM | D26: 238000 | F26: =SUM(D26:E26) -> 238000 | L26: 238000 | O26: =SUM(G26:N26) -> 238000
A27: 23 | B27: 46286 | C27: ALI SADAAT (MANDWAL, CHAKRI) | E27: 216000 | F27: =SUM(D27:E27) -> 216000 | L27: 216000 | O27: =SUM(G27:N27) -> 216000
A28: 24 | B28: 46279 | C28: PCI | D28: 204000 | F28: =SUM(D28:E28) -> 204000 | G28: 0 | L28: 204000 | O28: =SUM(G28:N28) -> 204000
A29: 25 | B29: 46277 | C29: LEXUS | E29: 160000 | F29: =SUM(D29:E29) -> 160000 | M29: 160000 | O29: =SUM(G29:N29) -> 160000
A30: 26 | B30: 46295 | C30: CBU TAXILA | E30: 0 | F30: =SUM(D30:E30) -> 0 | J30: 0 | K30: 0 | O30: =SUM(G30:N30) -> 0
A31: 27 | B31: 46280 | C31: RECEIVED FROM ABL ACC | F31: =SUM(D31:E31) -> 0 | K31: 0 | O31: =SUM(G31:N31) -> 0
A32: 28 | B32: 46269 | C32: INNOVATIVE | E32: 64342 | F32: =SUM(D32:E32) -> 64342 | N32: 64342 | O32: =SUM(G32:N32) -> 64342
A33: 29 | C33: Inkling School | D33: 38000 | F33: =SUM(D33:E33) -> 38000 | G33: 0 | H33: 0 | L33: 38000 | O33: =SUM(G33:N33) -> 38000
A34: 30 | B34: 46274 | C34: TIGES | E34: =47800*3 -> 143400 | F34: =SUM(D34:E34) -> 143400 | J34: 47800 | K34: =47800*2 -> 95600 | O34: =SUM(G34:N34) -> 143400
A35: 31 | B35: 46273 | C35: Bin Zahid | E35: 36000 | F35: =SUM(D35:E35) -> 36000 | L35: 36000 | O35: =SUM(G35:N35) -> 36000
A36: TOTAL | D36: =SUM(D4:D35) -> 2848000 | E36: =SUM(E4:E35) -> 13530009 | F36: =SUM(F4:F35) -> 16378009 | G36: =SUM(G4:G35) -> 2254000 | H36: =SUM(H4:H35) -> 0 | O36: =SUM(G36:N36) -> 2254000
A37: TRANSFER INTER BANK | J37: =SUM(J4:J36) -> 2080533 | K37: =SUM(K4:K36) -> 13350459 | L37: =SUM(L4:L36) -> 1588133 | M37: =SUM(M4:M36) -> 215555 | N37: =SUM(N4:N36) -> 2515252
G38: =SUM(G36:G37) -> 2254000 | H38: =SUM(H36:H37) -> 0 | I38: =SUM(I36:I37) -> 0 | J38: =SUM(J36:J37) -> 2080533 | K38: =SUM(K36:K37) -> 13350459 | L38: =SUM(L36:L37) -> 1588133 | M38: =SUM(M36:M37) -> 215555 | N38: =SUM(N36:N37) -> 2515252
Q39: RECEIPT IN OFFICE
A40: CASH/BANK WITHDRAWAL STATE SEP 2026 | Q40: CASH | R40: CHEQUE | S40: TOTAL
...

Sheet SUMMARY PAY EXPENSE SHEET
A1: EXPENSE SHEET SUMMARY FTM SEP 2026
A2: SER NO. | B2: EXPENSE TYPE | C2: EMAAR | D2: TIGES SGC | E2: WUSAT | F2: NOVA ISB | G2: NOVA QTBL | H2: NOVA PSH | I2: NOVA CSD | J2: PREMIER SALES | K2: PCI/PFM/68 | L2: SGC-THALIAN | M2: PRG | N2: MANDWAL | O2: J SONS | P2: HMC/CBU | Q2: KALOON | R2: ELYSIUM | S2: DHA DENTAL CENTRE | T2: CBR | U2: DOLMEN | V2: SWEET PALACE | W2: RELEIVERS | X2: INKLING | Y2: AWT | Z2: MIU/MOMT | AA2: MR SALAAR | AB2: RISING SUN | AC2: OFFICE | AD2: TOTAL
A3: 1 | B3: SALARIES PAID | C3: ='EXPENSE SHEET'!H50 -> 3680263 | D3: ='EXPENSE SHEET'!I50 -> 0 | E3: ='EXPENSE SHEET'!J50 -> 39337 | F3: ='EXPENSE SHEET'!K50 -> 543129 | G3: ='EXPENSE SHEET'!L50 -> 100000 | H3: ='EXPENSE SHEET'!M50 -> 196000 | I3: ='EXPENSE SHEET'!N50 -> 322000 | J3: ='EXPENSE SHEET'!O50 -> 0 | ... AC3: ='EXPENSE SHEET'!AH50 -> 1503747 | AD3: =SUM(C3:AC3) -> 12680663
A4: 2 | B4: TOTAL ADVANCE PAYMENT | C4: ='EXPENSE SHEET'!H77 -> 5000 | D4: ='EXPENSE SHEET'!I77 -> 0 | E4: ='EXPENSE SHEET'!J77 -> 0 | F4: ='EXPENSE SHEET'!K77 -> 0 | G4: ='EXPENSE SHEET'!L77 -> 0 | H4: ='EXPENSE SHEET'!M77 -> 0 | I4: ='EXPENSE SHEET'!N77 -> 10000 | J4: ='EXPENSE SHEET'!O77 -> 0 | ... AC4: ='EXPENSE SHEET'!AH77 -> 0 | AD4: =SUM(C4:AC4) -> 30000
A5: 3 | B5: EXPENSE INCURRED ON SALARIES DISTRIBUTION | C5: ='EXPENSE SHEET'!H79 -> 0 | D5: ='EXPENSE SHEET'!I79 -> 0 | E5: ='EXPENSE SHEET'!J79 -> 0 | F5: ='EXPENSE SHEET'!K79 -> 0 | G5: ='EXPENSE SHEET'!L79 -> 0 | H5: ='EXPENSE SHEET'!M79 -> 0 | I5: ='EXPENSE SHEET'!N79 -> 0 | J5: ='EXPENSE SHEET'!O79 -> 0 | ... V5: ='EXPENSE SHEET'!AA79 -> 0 | W5: ='EXPENSE SHEET'!AB52 -> 0 | X5: ='EXPENSE SHEET'!AC52 -> 0 | Y5: ='EXPENSE SHEET'!AD52 -> 0 | Z5: ='EXPENSE SHEET'!AE52 -> 0 | AA5: ='EXPENSE SHEET'!AF79 -> 0 | AB5: ='EXPENSE SHEET'!AG79 -> 0 | AC5: ='EXPENSE SHEET'!AH79 -> 0 | AD5: =SUM(C5:AC5) -> 0
A6: 4 | B6: TOTAL TRAVEL EXPENSE | C6: ='EXPENSE SHEET'!H140 -> 220 | D6: ='EXPENSE SHEET'!I140 -> 0 | E6: ='EXPENSE SHEET'!J140 -> 0 | F6: ='EXPENSE SHEET'!K140 -> 0 | G6: ='EXPENSE SHEET'!L140 -> 0 | H6: ='EXPENSE SHEET'!M140 -> 0 | I6: ='EXPENSE SHEET'!N140 -> 0 | J6: ='EXPENSE SHEET'!O140 -> 0 | ... AC6: ='EXPENSE SHEET'!AH140 -> 90773 | AD6: =SUM(C6:AC6) -> 94151
A7: 5 | B7: TOTAL FOOD EXPENSE | C7: ='EXPENSE SHEET'!H156 -> 0 | D7: ='EXPENSE SHEET'!I156 -> 0 | E7: ='EXPENSE SHEET'!J156 -> 0 | F7: ='EXPENSE SHEET'!K156 -> 0 | G7: ='EXPENSE SHEET'!L156 -> 0 | H7: ='EXPENSE SHEET'!M156 -> 0 | I7: ='EXPENSE SHEET'!N156 -> 0 | J7: ='EXPENSE SHEET'!O156 -> 0 | ... AC7: ='EXPENSE SHEET'!AH156 -> 9330 | AD7: =SUM(C7:AC7) -> 10830
A8: 6 | B8: TOTAL TEABREAK EXPENSE | C8: ='EXPENSE SHEET'!H160 -> 0 | D8: ='EXPENSE SHEET'!I160 -> 0 | E8: ='EXPENSE SHEET'!J160 -> 0 | F8: ='EXPENSE SHEET'!K160 -> 0 | G8: ='EXPENSE SHEET'!L160 -> 0 | H8: ='EXPENSE SHEET'!M160 -> 0 | I8: ='EXPENSE SHEET'!N160 -> 0 | J8: ='EXPENSE SHEET'!O160 -> 0 | ... AC8: ='EXPENSE SHEET'!AH160 -> 7680 | AD8: =SUM(C8:AC8) -> 7680
A9: 7 | B9: TOTAL STATIONERY EXPENSE | C9: ='EXPENSE SHEET'!H164 -> 0 | D9: ='EXPENSE SHEET'!I164 -> 0 | E9: ='EXPENSE SHEET'!J164 -> 0 | F9: ='EXPENSE SHEET'!K164 -> 0 | G9: ='EXPENSE SHEET'!L164 -> 0 | H9: ='EXPENSE SHEET'!M164 -> 0 | I9: ='EXPENSE SHEET'!N164 -> 0 | J9: ='EXPENSE SHEET'!O164 -> 0 | ... AC9: ='EXPENSE SHEET'!AH164 -> 0 | AD9: =SUM(C9:AC9) -> 0
A10: 8 | B10: TOTAL RENT UTILITIES & INTERNET EXPENSE | C10: ='EXPENSE SHEET'!H176 -> 0 | D10: ='EXPENSE SHEET'!I176 -> 0 | E10: ='EXPENSE SHEET'!J176 -> 0 | F10: ='EXPENSE SHEET'!K176 -> 0 | G10: ='EXPENSE SHEET'!L176 -> 0 | H10: ='EXPENSE SHEET'!M176 -> 0 | I10: ='EXPENSE SHEET'!N176 -> 0 | J10: ='EXPENSE SHEET'!O176 -> 0 | ... AC10: ='EXPENSE SHEET'!AH176 -> 657745 | AD10: =SUM(C10:AC10) -> 657745
A11: 9 | B11: TOTAL INVENTORY EXPENSE | C11: ='EXPENSE SHEET'!H184 -> 0 | D11: ='EXPENSE SHEET'!I184 -> 0 | E11: ='EXPENSE SHEET'!J184 -> 0 | F11: ='EXPENSE SHEET'!K184 -> 0 | G11: ='EXPENSE SHEET'!L184 -> 0 | H11: ='EXPENSE SHEET'!M184 -> 0 | I11: ='EXPENSE SHEET'!N184 -> 0 | J11: ='EXPENSE SHEET'!O184 -> 0 | ... AC11: ='EXPENSE SHEET'!AH184 -> 292750 | AD11: =SUM(C11:AC11) -> 292750
A12: 10 | B12: TOTAL LEGAL EXPENSE | C12: ='EXPENSE SHEET'!H191 -> 0 | D12: ='EXPENSE SHEET'!I191 -> 0 | E12: ='EXPENSE SHEET'!J191 -> 0 | F12: ='EXPENSE SHEET'!K191 -> 0 | G12: ='EXPENSE SHEET'!L191 -> 0 | H12: ='EXPENSE SHEET'!M191 -> 0 | I12: ='EXPENSE SHEET'!N191 -> 0 | J12: ='EXPENSE SHEET'!O191 -> 0 | ... AC12: ='EXPENSE SHEET'!AH191 -> 237269 | AD12: =SUM(C12:AC12) -> 518832
A13: 13 | B13: TOTAL MISCELLENIOUS EXPENSE | C13: ='EXPENSE SHEET'!H227 -> 0 | D13: ='EXPENSE SHEET'!I227 -> 0 | E13: ='EXPENSE SHEET'!J227 -> 0 | F13: ='EXPENSE SHEET'!K227 -> 0 | G13: ='EXPENSE SHEET'!L227 -> 0 | H13: ='EXPENSE SHEET'!M227 -> 0 | I13: ='EXPENSE SHEET'!N227 -> 0 | J13: ='EXPENSE SHEET'!O227 -> 0 | ... AC13: ='EXPENSE SHEET'!AH227 -> 50500 | AD13: =SUM(C13:AC13) -> 96902
A14: 12 | B14: TOTAL DRAWINGS BY CEO / CFO | C14: ='EXPENSE SHEET'!H234 -> 0 | D14: ='EXPENSE SHEET'!I234 -> 0 | E14: ='EXPENSE SHEET'!J234 -> 0 | F14: ='EXPENSE SHEET'!K234 -> 0 | G14: ='EXPENSE SHEET'!L234 -> 0 | H14: ='EXPENSE SHEET'!M234 -> 0 | I14: ='EXPENSE SHEET'!N234 -> 0 | J14: ='EXPENSE SHEET'!O234 -> 0 | ... AC14: ='EXPENSE SHEET'!AH234 -> 197410 | AD14: =SUM(C14:AC14) -> 197410
A15: GRAND TOTAL | C15: =SUM(C3:C14) -> 3685483 | D15: =SUM(D3:D14) -> 0 | E15: =SUM(E3:E14) -> 39337 | F15: =SUM(F3:F14) -> 543129 | G15: =SUM(G3:G14) -> 100000 | H15: =SUM(H3:H14) -> 196000 | I15: =SUM(I3:I14) -> 332000 | J15: =SUM(J3:J14) -> 0 | ... AD15: =SUM(AD3:AD14) -> 14586963
A17: PROFIT PER PROJECT
B18: INCOME RECEIVED | C18: ='INCOME WITHDRWAL STATE'!O7 -> 4754162 | D18: ='INCOME WITHDRWAL STATE'!F34 -> 143400 | E18: ='INCOME WITHDRWAL STATE'!O5 -> 264000 | F18: 0 | K18: ='INCOME WITHDRWAL STATE'!T5 -> 646000 | L18: ='INCOME WITHDRWAL STATE'!O25 -> 745927 | M18: ='INCOME WITHDRWAL STATE'!O20 -> 65340 | N18: ='INCOME WITHDRWAL STATE'!O27 -> 216000 | O18: ='INCOME WITHDRWAL STATE'!O17 -> 38500 | P18: ='INCOME WITHDRWAL STATE'!F15+'INCOME WITHDRWAL STATE'!F30 -> 4629379 | Q18: ='INCOME WITHDRWAL STATE'!O14 -> 24000 | R18: ='INCOME WITHDRWAL STATE'!O6 -> 36000 | S18: ='INCOME WITHDRWAL STATE'!O8 -> 35500 | T18: ='INCOME WITHDRWAL STATE'!F12 -> 428544 | U18: ='INCOME WITHDRWAL STATE'!F23 -> 510152 | V18: ='INCOME WITHDRWAL STATE'!O21 -> 90000 | W18: 0 | X18: ='INCOME WITHDRWAL STATE'!O33 -> 38000 | Y18: ='INCOME WITHDRWAL STATE'!O22 -> 148000 | Z18: ='INCOME WITHDRWAL STATE'!F11 -> 1246511 | AB18: ='INCOME WITHDRWAL STATE'!F19 -> 90000 | AC18: 0 | AD18: =SUM(C18:AC18) -> 14149415
B19: PROFIT | C19: =C18-C15 -> 1068679 | D19: =D18-D15 -> 143400 | E19: =E18-E15 -> 224663 | F19: =F18-F15 -> -543129 | G19: =G18-G15 -> -100000 | H19: =H18-H15 -> -196000 | I19: =I18-I15 -> -332000 | J19: =J18-J15 -> 0 | ... AC19: =AC18-AC15 -> -3047204 | AD19: =SUM(C19:AC19) -> -437548

Sheet EXPENSE SHEET
A1: EXPENSE SHEET SUMMARY FTM SEP 2026
A2: SER NO. | B2: EXPENSE TYPE | C2: EXPENSE SUB - TYPE | D2: ENTRY NO. | E2: DATE | F2: DETAIL/PARTICULAR | G2: EXPENDED/DISTRIBUTED BY | H2: EMAAR | I2: TIGES SGC | J2: WUSAT | K2: NOVA ISB | L2: NOVA QTBL | M2: NOVA PSH | N2: NOVA CSD | O2: PREMIER SALES | P2: PCI | Q2: SGC-THALIAN | R2: PRG | S2: MANDWAL | T2: J SONS | U2: HMC | V2: FREELINE | W2: LEXUS | X2: DHA DENTAL CENTRE | Y2: CBR | Z2: DOLMEN | AA2: SWEET PALACE | AB2: RELEIVERS | AC2: INKLING | AD2: AWT | AE2: MIU/MOMT | AF2: MR SALAAR | AG2: RISING SUN | AH2: OFFICE | AI2: TOTAL | AJ2: REMARKS
A3: 1 | B3: SALARY | C3: PAY | E3: 46267 | F3: SALARY OF RISING SUN 2X GD | AG3: 80000 | AH3: 0 | AI3: =SUM(H3:AH3) -> 80000
A4: 2 | B4: SALARY | C4: PAY | E4: 46270 | F4: SALARY OF 53X EMAAR GDS | H4: 2814598 | AH4: 0 | AI4: =SUM(H4:AH4) -> 2814598
A5: 3 | B5: SALARY | C5: PAY | E5: 46270 | F5: SALARY OF 13X EMAAR GDS | H5: 706601 | AH5: 0 | AI5: =SUM(H5:AH5) -> 706601
A6: 4 | B6: SALARY | C6: PAY | E6: 46270 | F6: SALARY OF 1X INKLING GUARD | AC6: 28000 | AH6: 0 | AI6: =SUM(H6:AH6) -> 28000
A7: 5 | B7: SALARY | C7: PAY | E7: 46273 | F7: SALARY 2X GDS SWEET PALACE | AA7: 64000 | AH7: 0 | AI7: =SUM(H7:AH7) -> 64000
A8: 6 | B8: SALARY | C8: PAY | E8: 46273 | F8: SALARY OF 1X J SONS GD | T8: 24000 | AH8: 0 | AI8: =SUM(H8:AH8) -> 24000
A9: 7 | B9: SALARY | C9: PAY | E9: 46270 | F9: SALARY OF NOVA GD AUG AND SEP CLEARED | K9: 47000 | AH9: 0 | AI9: =SUM(H9:AH9) -> 47000
A10: 8 | B10: SALARY | C10: PAY | E10: 46274 | F10: SALARY OF RELEIVER RIAZ | AB10: 25000 | AH10: 0 | AI10: =SUM(H10:AH10) -> 25000
A11: 9 | B11: SALARY | C11: PAY | E11: 46272 | F11: SALARY OF GUL REHMAN | AH11: 55000 | AI11: =SUM(H11:AH11) -> 55000
A12: 10 | B12: SALARY | C12: PAY | E12: 46275 | F12: SALARY OF MIU CAMP OFFICE | AH12: 35000 | AI12: =SUM(H12:AH12) -> 35000
A13: 11 | B13: SALARY | C13: PAY | E13: 46275 | F13: SALARY OF 5X WUSAT GUARDS | AH13: 161747 | AI13: =SUM(H13:AH13) -> 161747
A14: 12 | B14: SALARY | C14: PAY | E14: 46275 | F14: SALARY OF DHA DENTAL GUARD | AH14: 28000 | AI14: =SUM(H14:AH14) -> 28000
A15: 13 | B15: SALARY | C15: PAY | E15: 46275 | F15: SALARY OF 4X AWT GUARDS | AD15: 91419 | AH15: 0 | AI15: =SUM(H15:AH15) -> 91419
A16: 14 | B16: SALARY | C16: PAY | E16: 46275 | F16: SALARY OF 6X DOLMEN GDS | Z16: 223000 | AH16: 0 | AI16: =SUM(H16:AH16) -> 223000 | AN16: 385774
A17: 15 | B17: SALARY | C17: PAY | E17: 46275 | F17: SALARY OF LEXUS AND MIMC | AH17: 899000 | AI17: =SUM(H17:AH17) -> 899000 | AN17: -165355
A18: 16 | B18: SALARY | C18: PAY | E18: 46276 | F18: SALARY OF 5X OFFICE STAFF | AH18: 270000 | AI18: =SUM(H18:AH18) -> 270000
A19: 17 | B19: SALARY | C19: PAY | E19: 46276 | F19: SALARY OF 3X DOLMEN GDS | Z19: 111000 | AH19: 0 | AI19: =SUM(H19:AH19) -> 111000
A20: 18 | B20: SALARY | C20: PAY | E20: 46276 | F20: SALARY OF 1X WUSAT GD | J20: 6307 | AH20: 0 | AI20: =SUM(H20:AH20) -> 6307
A21: 19 | B21: SALARY | C21: PAY | E21: 46276 | F21: SALARY OF 4X EMAAR GDS | H21: 159064 | AH21: 0 | AI21: =SUM(H21:AH21) -> 159064
A22: 20 | B22: SALARY | C22: PAY | E22: 46276 | F22: SALARY OF 1X WUSAT GD | J22: 33030 | AH22: 0 | AI22: =SUM(H22:AH22) -> 33030
A23: 21 | B23: SALARY | C23: PAY | E23: 46276 | F23: SALARY OF 103X SALARY OF HMC GUARDS | U23: 3999775 | AH23: 0 | AI23: =SUM(H23:AH23) -> 3999775
A24: 22 | B24: SALARY | C24: PAY | E24: 46279 | F24: SALARIES OF PCI | P24: 530548 | AH24: 0 | AI24: =SUM(H24:AH24) -> 530548
A25: 23 | B25: SALARY | C25: PAY | E25: 46283 | F25: SALARY OF NOVA ISB GD USMAN HAIDER | K25: 25000 | AH25: 0 | AI25: =SUM(H25:AH25) -> 25000
A26: 24 | B26: SALARY | C26: PAY | E26: 46286 | F26: PRG SALARIES | R26: 49000 | AH26: 0 | AI26: =SUM(H26:AH26) -> 49000
A27: 25 | B27: SALARY | C27: PAY | E27: 46286 | F27: MANDWAAL SALARIES | S27: 50000 | AH27: 0 | AI27: =SUM(H27:AH27) -> 50000
A28: 26 | B28: SALARY | C28: PAY | E28: 46283 | F28: SALARY OF 6X HMC GUARDS SALARY | U28: 237600 | AH28: 0 | AI28: =SUM(H28:AH28) -> 237600
A29: 27 | B29: SALARY | C29: PAY | E29: 46283 | F29: SALARY OF BISMILLAH JAN NOVA PSH | M29: 26000 | AH29: 0 | AI29: =SUM(H29:AH29) -> 26000
A30: 28 | B30: SALARY | C30: PAY | E30: 46287 | F30: SALARY OF 2X HMC GUARDS | U30: 57587 | AH30: 0 | AI30: =SUM(H30:AH30) -> 57587
A31: 29 | B31: SALARY | C31: PAY | E31: 46287 | F31: SGC SALARIES | Q31: 467258 | AH31: 0 | AI31: =SUM(H31:AH31) -> 467258
A32: 30 | B32: SALARY | C32: PAY | E32: 46294 | F32: SALARIES OF NOVA ISB | K32: 471129 | AH32: 0 | AI32: =SUM(H32:AH32) -> 471129
A33: 31 | B33: SALARY | C33: PAY | E33: 46294 | F33: SALARIES OF NOVA PSH | M33: 170000 | AH33: 0 | AI33: =SUM(H33:AH33) -> 170000
A34: 32 | B34: SALARY | C34: PAY | E34: 46294 | F34: SALARIES OF NOVA CHD | N34: 322000 | AH34: 0 | AI34: =SUM(H34:AH34) -> 322000
A35: 33 | B35: SALARY | C35: PAY | E35: 46294 | F35: SALARIES OF NOVA QTBL | L35: 100000 | AH35: 0 | AI35: =SUM(H35:AH35) -> 100000
A36: 34 | B36: SALARY | C36: PAY | E36: 46295 | F36: SALARY OF MUHAMMAD ZAMIR FTM SEP 26 | AH36: 55000 | AI36: =SUM(H36:AH36) -> 55000
A37: 35 | B37: SALARY | C37: PAY | E37: 46276 | F37: CHEQUE FOR MIU SAL | AE37: 258000 | AH37: 0 | AI37: =SUM(H37:AH37) -> 258000
A38: 36 | B38: SALARY | C38: PAY | AH38: 0 | AI38: =SUM(H38:AH38) -> 0
A39: 37 | B39: SALARY | C39: PAY | AH39: 0 | AI39: =SUM(H39:AH39) -> 0
A40: 38 | B40: SALARY | C40: PAY | AH40: 0 | AI40: =SUM(H40:AH40) -> 0
...

Sheet P&L
B2: PROFIT AND LOSS STATEMENT
B3: Revenue | G3: ='INCOME WITHDRWAL STATE'!F36 -> 16378009 | J3: MIU INCLUDED
B4: Expenses
B5: SALARIES PAID | E5: ='SUMMARY PAY EXPENSE SHEET'!AD3 -> 12680663
B6: TOTAL ADVANCE PAYMENT | E6: ='SUMMARY PAY EXPENSE SHEET'!AD4 -> 30000
B7: EXPENSE INCURRED ON SALARIES DISTRIBUTION | E7: ='SUMMARY PAY EXPENSE SHEET'!AD5 -> 0
B8: TOTAL TRAVEL EXPENSE | E8: ='SUMMARY PAY EXPENSE SHEET'!AD6 -> 94151
B9: TOTAL FOOD EXPENSE | E9: ='SUMMARY PAY EXPENSE SHEET'!AD7 -> 10830
B10: TOTAL TEABREAK EXPENSE | E10: ='SUMMARY PAY EXPENSE SHEET'!AD8 -> 7680
B11: TOTAL STATIONERY EXPENSE | E11: ='SUMMARY PAY EXPENSE SHEET'!AD9 -> 0
B12: TOTAL RENT UTILITIES & INTERNET EXPENSE | E12: ='SUMMARY PAY EXPENSE SHEET'!AD10 -> 657745
B13: TOTAL INVENTORY EXPENSE | E13: ='SUMMARY PAY EXPENSE SHEET'!AD11 -> 292750
B14: TOTAL LEGAL EXPENSE | E14: ='SUMMARY PAY EXPENSE SHEET'!AD12 -> 518832 | L14: 1678890
B15: TOTAL MISCELLENIOUS EXPENSE | E15: ='SUMMARY PAY EXPENSE SHEET'!AD13 -> 96902 | L15: =L14-102550 -> 1576340 | O15: 1523828 | Q15: =L15-O15 -> 52512
B16: TOTAL DRAWINGS BY CEO / CFO | E16: ='SUMMARY PAY EXPENSE SHEET'!AD14 -> 197410
B17: TOTAL EXPENSES | E17: =SUM(E5:F16) -> 14586963
B18: PROFIT /LOSS | H18: =G3-E17 -> 1791046 | L18: =G3-L15-E5 -> 2121006 | O18: 2185314 | Q18: =L18-O18 -> -64308
L19: =L18*0.25 -> 530251.5
